<?xml version='1.0'?>
<sdf version='1.4'>
  <model name="simple_robot">
    <static>false</static>

    <link name="chassis">
      <pose>0 0 .1 0 0 0</pose>
      <gravity>true</gravity>

      <inertial>
        <pose>0 0 0 0 0 0</pose>
        <mass>5</mass>
        <inertia>
          <ixx>0.092708</ixx>
          <ixy>0</ixy>
          <ixz>0</ixz>
          <iyy>0.104167</iyy>
          <iyz>0</iyz>
          <izz>0.063542</izz>
        </inertia>
      </inertial>

      <collision name="collision">
        <geometry>
          <box>
            <size>.3 .25 .4</size>
          </box>
        </geometry>
      </collision>

      <visual name="visual">
        <pose>0 0 0 0 0 0</pose>
        <geometry>
          <box>
            <size>.3 .25 .4</size>
          </box>
        </geometry>
      </visual>

      <collision name="caster_collision">
        <pose>-0.075 0 -0.2 0 0 0</pose>
        <geometry>
          <sphere>
            <radius>.05</radius>
          </sphere>
        </geometry>

        <surface>
          <friction>
            <ode>
              <mu>0</mu>
              <mu2>0</mu2>
              <slip1>1.0</slip1>
              <slip2>1.0</slip2>
            </ode>
          </friction>
        </surface>
      </collision>

      <visual name="caster_visual">
        <pose>-0.075 0 -0.2 0 0 0</pose>
        <geometry>
          <sphere>
            <radius>.05</radius>
          </sphere>
        </geometry>
      </visual>
    </link>

    <link name="left_wheel">
      <pose>0.1 0.13 -0.1 0 1.5707 1.5707</pose>
      <gravity>true</gravity>

      <inertial>
        <pose>0 0 0 0 0 0</pose>
        <mass>0.3</mass>
        <inertia>
          <ixx>0.00025</ixx>
          <ixy>0</ixy>
          <ixz>0</ixz>
          <iyy>0.00025</iyy>
          <iyz>0</iyz>
          <izz>0.000375</izz>
        </inertia>
      </inertial>

      <collision name="collision">
        <geometry>
          <cylinder>
            <radius>.05</radius>
            <length>.05</length>
          </cylinder>
        </geometry>
      </collision>

      <visual name="visual">
        <geometry>
          <cylinder>
            <radius>.05</radius>
            <length>.05</length>
          </cylinder>
        </geometry>
      </visual>
    </link>

    <joint type="revolute" name="left_wheel_hinge">
      <child>left_wheel</child>
      <parent>chassis</parent>
      <axis>
        <xyz>0 1 0</xyz>
      </axis>
    </joint>

    <link name="left_encoder_wheel">
      <pose>0.1 0.1 -0.1 0 1.5707 1.5707</pose>
      <gravity>true</gravity>

      <inertial>
        <pose>0 0 0 0 0 0</pose>
        <mass>0.03</mass>
        <inertia>
          <ixx>0.000019</ixx>
          <ixy>0</ixy>
          <ixz>0</ixz>
          <iyy>0.000019</iyy>
          <iyz>0</iyz>
          <izz>0.000038</izz>
        </inertia>
      </inertial>

      <collision name="collision">
        <geometry>
          <cylinder>
            <radius>.05</radius>
            <length>.005</length>
          </cylinder>
        </geometry>

        <surface>
          <friction>
            <ode>
              <mu>1</mu>
              <mu2>1</mu2>
              <slip1>0</slip1>
              <slip2>0</slip2>
            </ode>
          </friction>
        </surface>
      </collision>

      <visual name="visual">
        <geometry>
          <cylinder>
            <radius>.05</radius>
            <length>.005</length>
          </cylinder>
        </geometry>
      </visual>
    </link>

    <joint type="revolute" name="left_encoder">
      <child>left_encoder_wheel</child>
      <parent>chassis</parent>
      <axis>
        <xyz>0 1 0</xyz>
      </axis>
    </joint>

    <link name="right_wheel">
      <pose>0.1 -0.13 -0.1 0 1.5707 1.5707</pose>
      <gravity>true</gravity>

      <inertial>
        <pose>0 0 0 0 0 0</pose>
        <mass>0.3</mass>
        <inertia>
          <ixx>0.00025</ixx>
          <ixy>0</ixy>
          <ixz>0</ixz>
          <iyy>0.00025</iyy>
          <iyz>0</iyz>
          <izz>0.000375</izz>
        </inertia>
      </inertial>

      <collision name="collision">
        <geometry>
          <cylinder>
            <radius>.05</radius>
            <length>.05</length>
          </cylinder>
        </geometry>
      </collision>

      <visual name="visual">
        <geometry>
          <cylinder>
            <radius>.05</radius>
            <length>.05</length>
          </cylinder>
        </geometry>
      </visual>
    </link>

    <joint type="revolute" name="right_wheel_hinge">
      <child>right_wheel</child>
      <parent>chassis</parent>
      <axis>
        <xyz>0 1 0</xyz>
      </axis>
    </joint>

    <link name="right_encoder_wheel">
      <pose>0.1 -0.1 -0.1 0 1.5707 1.5707</pose>
      <gravity>true</gravity>

      <inertial>
        <pose>0 0 0 0 0 0</pose>
        <mass>0.03</mass>
        <inertia>
          <ixx>0.000019</ixx>
          <ixy>0</ixy>
          <ixz>0</ixz>
          <iyy>0.000019</iyy>
          <iyz>0</iyz>
          <izz>0.000038</izz>
        </inertia>
      </inertial>

      <collision name="collision">
        <geometry>
          <cylinder>
            <radius>.05</radius>
            <length>.005</length>
          </cylinder>
        </geometry>

        <surface>
          <friction>
            <ode>
              <mu>1</mu>
              <mu2>1</mu2>
              <slip1>0</slip1>
              <slip2>0</slip2>
            </ode>
          </friction>
        </surface>
      </collision>

      <visual name="visual">
        <geometry>
          <cylinder>
            <radius>.05</radius>
            <length>.005</length>
          </cylinder>
        </geometry>
      </visual>
    </link>

    <joint type="revolute" name="right_encoder">
      <child>right_encoder_wheel</child>
      <parent>chassis</parent>
      <axis>
        <xyz>0 1 0</xyz>
      </axis>
    </joint>

    <!--
    <include>
      <uri>model://hokuyo</uri>
      <pose>0.2 0 0.2 0 0 0</pose>
    </include>
    <joint name="hokuyo_joint" type="revolute">
      <child>hokuyo::link</child>
      <parent>chassis</parent>
      <axis>
        <xyz>0 0 1</xyz>
        <limit>
          <upper>0</upper>
          <lower>0</lower>
        </limit>
      </axis>
    </joint>
    -->


  <plugin name="control" filename="libcontrol_plugin.so"/>
  <!--
  <plugin name="pose" filename="libpose_plugin.so"/>
  <plugin name="tester" filename="libtester_plugin.so"/>

    <plugin name="encoder" filename="libencoder_plugin.so">
      <topic>~/encoders</topic>
    </plugin>

    <plugin name="motor_plugin" filename="libmotor_plugin.so">
      <topic>~/motors_control</topic>
      <multiplier>1</multiplier>
    </plugin>
  -->
  </model>
</sdf>
